<mujoco model="deskbot">
  <!--
    DeskBot — Self-balancing two-wheeled desktop robot.
    Coordinate system: X=forward, Y=left, Z=up.
    Wheel radius: 10cm, body ~18cm tall, total ~21cm from ground.

    This file describes the robot only (no environment).
    Use scene.xml for a complete simulation with ground and lighting.
  -->

  <compiler angle="radian"/>

  <default>
    <joint damping="0.008" armature="0.001"/>
    <geom friction="1.2 0.005 0.001" condim="4" contype="1" conaffinity="1"
          solref="0.005 1.0"/>
    <motor ctrlrange="-3.0 3.0"/>

    <default class="wheel">
      <joint damping="0.003"/>
      <geom material="tire" mass="0.05"/>
    </default>
    <default class="hub">
      <geom material="wheel" contype="0" conaffinity="0" mass="0.005"/>
    </default>
    <default class="visual">
      <geom contype="0" conaffinity="0" mass="0.001"/>
    </default>
  </default>

  <asset>
    <material name="chassis" rgba="0.18 0.20 0.24 1" specular="0.6" shininess="0.4"/>
    <material name="body"    rgba="0.22 0.50 0.72 1" specular="0.5" shininess="0.3"/>
    <material name="accent"  rgba="0.90 0.35 0.15 1" specular="0.4" shininess="0.2"/>
    <material name="screen"  rgba="0.15 0.85 0.55 1" specular="0.8" shininess="0.9"
              emission="0.4"/>
    <material name="wheel"   rgba="0.12 0.12 0.12 1" specular="0.2" shininess="0.05"/>
    <material name="tire"    rgba="0.08 0.08 0.08 1" specular="0.05" shininess="0.01"/>
  </asset>

  <worldbody>
    <body name="chassis" pos="0 0 0.10">
      <joint type="free"/>
      <!-- No explicit <inertial>: MuJoCo computes CoM from geom masses.
           Mass distribution: light base, heavy head → CoM above axle
           for inverted pendulum dynamics. -->

      <!-- Motor housing (base) — cylinder centered on wheel axle (Y-axis).
           Radius 9cm < wheel radius 10cm = 10mm constant ground clearance
           at any pitch angle. Upper part hidden inside body; bottom arc
           acts as a curved skid plate. -->
      <geom name="base" type="cylinder" size="0.09 0.065"
            pos="0 0 0" euler="1.5708 0 0"
            mass="0.05" material="chassis"/>

      <!-- Main body — cubic block, straddles axle -->
      <geom name="body" type="box" size="0.05 0.058 0.055"
            pos="0 0 0.015" mass="0.35" material="body"/>

      <!-- Head (battery + electronics → heavy) -->
      <geom name="head" type="box" size="0.04 0.048 0.016"
            pos="0 0 0.086" mass="0.18" material="accent"/>

      <!-- Sensor pod — platform 1cm above head hosting 10× VL53L0X modules.
           Enlarged (7×7cm) to fit the full fovea + peripheral + rear array.
           Wheel clearance: sensor origins sit at Z=0.112 (local); wheel top
           is at Z=0.10 (axle) + 0.10 (radius) = 0.20 world; chassis is at
           Z=0.10 world, so sensor world Z = 0.212 > 0.20 → 12mm margin.
           Lateral clearance: pod Y extent ±0.035, wheels at |Y|=0.08 →
           45mm margin. -->
      <geom name="sensor_pod" type="box" size="0.035 0.035 0.005"
            pos="0 0 0.107" mass="0.02" material="chassis"/>

      <!-- Front screen / LED indicator -->
      <geom name="screen" type="box" size="0.001 0.035 0.030"
            pos="0.051 0 0.015" material="screen" class="visual"/>

      <!-- Face indicator on head -->
      <geom name="face" type="box" size="0.001 0.020 0.010"
            pos="0.041 0 0.086" material="screen" class="visual"/>

      <!-- IMU sensor site (near CoM) -->
      <site name="imu" pos="0 0 0.0" size="0.003" rgba="1 0 0 0.5"/>

      <!-- Camera mount site (on head, forward-facing) -->
      <site name="cam_mount" pos="0.04 0 0.086" zaxis="1 0 0" size="0.005"
            rgba="0.2 0.2 0.2 1"/>

      <!-- VL53L0X rangefinder array — 10 sensors, all HIGH mount on pod.
           Layout is foveal: 3 parallel beams in a dense forward cluster
           (C, FL, FR) cover the column the robot physically sweeps while
           going straight; peripheral beams spread out logarithmically
           (L/R=±25°, WL/WR=±55°, SL/SR=±90°) for obstacle scanning and
           corridor following; a single rear beam (B) watches behind.

           All beams share a -5° downward tilt so that on perfectly flat
           ground they eventually intersect the floor well before MAX_RANGE,
           giving GroundGeometry a flat-ground expectation for each ray.
           Hardware mapping: 2× TCA9548A I²C multiplexers with 1 sensor
           per channel (10 channels used out of 16). All physical modules
           share the same VL53L0X factory address 0x29 — the mux resolves
           the collision with zero re-addressing.
           Tilt factor: cos(5°)=0.9962, sin(5°)=0.0872 -->

      <!-- ── Fovea: 3 parallel forward beams, covering the robot's width ── -->
      <!-- C: fovea center — parallel forward, -5° tilt -->
      <site name="rf_C"  pos="0.035  0.000 0.112"
            zaxis="0.9962 0 -0.0872"
            size="0.004" rgba="1 0.2 0.2 0.9"/>
      <!-- FL: fovea left — parallel forward, offset +Y -->
      <site name="rf_FL" pos="0.035  0.018 0.112"
            zaxis="0.9962 0 -0.0872"
            size="0.004" rgba="1 0.2 0.2 0.9"/>
      <!-- FR: fovea right — parallel forward, offset -Y -->
      <site name="rf_FR" pos="0.035 -0.018 0.112"
            zaxis="0.9962 0 -0.0872"
            size="0.004" rgba="1 0.2 0.2 0.9"/>

      <!-- ── Mid-forward: ±25° ── -->
      <!-- L: mid-forward-left +25° — cos25=0.9063, sin25=0.4226 -->
      <site name="rf_L"  pos="0.028  0.030 0.112"
            zaxis="0.9028 0.4210 -0.0872"
            size="0.004" rgba="1 0.5 0.2 0.8"/>
      <!-- R: mid-forward-right -25° -->
      <site name="rf_R"  pos="0.028 -0.030 0.112"
            zaxis="0.9028 -0.4210 -0.0872"
            size="0.004" rgba="1 0.5 0.2 0.8"/>

      <!-- ── Wide-forward: ±55° (kept from the earlier sweep optimum) ── -->
      <!-- WL: wide-forward-left +55° — cos55=0.5736, sin55=0.8192 -->
      <site name="rf_WL" pos="0.018  0.034 0.112"
            zaxis="0.5714 0.8161 -0.0872"
            size="0.004" rgba="1 0.6 0.2 0.8"/>
      <!-- WR: wide-forward-right -55° -->
      <site name="rf_WR" pos="0.018 -0.034 0.112"
            zaxis="0.5714 -0.8161 -0.0872"
            size="0.004" rgba="1 0.6 0.2 0.8"/>

      <!-- ── Pure side: ±90° (corridor tracking) ── -->
      <!-- SL: side-left +90° -->
      <site name="rf_SL" pos="0.000  0.034 0.112"
            zaxis="0 0.9962 -0.0872"
            size="0.004" rgba="1 0.2 0.2 0.8"/>
      <!-- SR: side-right -90° -->
      <site name="rf_SR" pos="0.000 -0.034 0.112"
            zaxis="0 -0.9962 -0.0872"
            size="0.004" rgba="1 0.2 0.2 0.8"/>

      <!-- ── Rear: single 180° beam ── -->
      <!-- B: rear-center, looking backward -->
      <site name="rf_B"  pos="-0.035 0.000 0.112"
            zaxis="-0.9962 0 -0.0872"
            size="0.004" rgba="0.6 0.2 1 0.9"/>

      <!-- Left wheel (R=10cm, tight to body: 13mm gap) -->
      <body name="wheel_L" pos="0 0.08 0">
        <joint name="wheel_L" type="hinge" axis="0 1 0" class="wheel"/>
        <geom name="tire_L" type="cylinder" size="0.10 0.009"
              euler="1.5708 0 0" class="wheel"/>
        <geom name="hub_L" type="cylinder" size="0.045 0.01"
              euler="1.5708 0 0" class="hub"/>
      </body>

      <!-- Right wheel (R=10cm, tight to body: 13mm gap) -->
      <body name="wheel_R" pos="0 -0.08 0">
        <joint name="wheel_R" type="hinge" axis="0 1 0" class="wheel"/>
        <geom name="tire_R" type="cylinder" size="0.10 0.009"
              euler="1.5708 0 0" class="wheel"/>
        <geom name="hub_R" type="cylinder" size="0.045 0.01"
              euler="1.5708 0 0" class="hub"/>
      </body>

      <!-- Robot-attached cameras -->
      <camera name="follow" mode="track" pos="0.8 -0.5 0.4"
              xyaxes="0.6 1 0 -0.2 0 1"/>
      <camera name="onboard" mode="fixed" pos="0.06 0 0.10"
              xyaxes="0 -1 0 0 0 1"/>
    </body>
  </worldbody>

  <actuator>
    <motor joint="wheel_L" name="motor_L" gear="1"/>
    <motor joint="wheel_R" name="motor_R" gear="1"/>
  </actuator>

  <sensor>
    <!-- IMU (MPU6050-like): accelerometer + gyroscope -->
    <accelerometer name="accel" site="imu"/>
    <gyro          name="gyro"  site="imu"/>
    <!-- Wheel encoders: angular velocity -->
    <jointvel name="enc_L" joint="wheel_L"/>
    <jointvel name="enc_R" joint="wheel_R"/>
    <!-- 10× VL53L0X rangefinders use custom mj_ray in sensors.py (not
         built-in rangefinder sensors) so the chassis body can be excluded
         from hits. Sites define ray origin + direction; raycasting runs
         in Python every physics tick. -->

  </sensor>
</mujoco>
